Workbook

Sheet Raw Data
A1: Sector | B1: Year | C1: Month | D1: Cereals and products | E1: Meat and fish | F1: Egg | G1: Milk and products | H1: Oils and fats | I1: Fruits | J1: Vegetables | K1: Pulses and products | L1: Sugar and Confectionery | M1: Spices | N1: Non-alcoholic beverages | O1: Prepared meals, snacks, sweets etc. | P1: Food and beverages | Q1: Pan, tobacco and intoxicants | R1: Clothing | S1: Footwear | T1: Clothing and footwear | U1: Housing | V1: Fuel and light | W1: Household goods and services | X1: Health | Y1: Transport and communication | Z1: Recreation and amusement | AA1: Education | AB1: Personal care and effects | AC1: Miscellaneous | AD1: General index
A2: Rural | B2: 2013 | C2: January | D2: 107.5 | E2: 106.3 | F2: 108.1 | G2: 104.9 | H2: 106.1 | I2: 103.9 | J2: 101.9 | K2: 106.1 | L2: 106.8 | M2: 103.1 | N2: 104.8 | O2: 106.7 | P2: 105.5 | Q2: 105.1 | R2: 106.5 | S2: 105.8 | T2: 106.4 | U2: NA | V2: 105.5 | W2: 104.8 | X2: 104 | Y2: 103.3 | Z2: 103.4 | AA2: 103.8 | AB2: 104.7 | AC2: 104 | AD2: 105.1
A3: Urban | B3: 2013 | C3: January | D3: 110.5 | E3: 109.1 | F3: 113 | G3: 103.6 | H3: 103.4 | I3: 102.3 | J3: 102.9 | K3: 105.8 | L3: 105.1 | M3: 101.8 | N3: 105.1 | O3: 107.9 | P3: 105.9 | Q3: 105.2 | R3: 105.9 | S3: 105 | T3: 105.8 | U3: 100.3 | V3: 105.4 | W3: 104.8 | X3: 104.1 | Y3: 103.2 | Z3: 102.9 | AA3: 103.5 | AB3: 104.3 | AC3: 103.7 | AD3: 104
A4: Rural+Urban | B4: 2013 | C4: January | D4: 108.4 | E4: 107.3 | F4: 110 | G4: 104.4 | H4: 105.1 | I4: 103.2 | J4: 102.2 | K4: 106 | L4: 106.2 | M4: 102.7 | N4: 104.9 | O4: 107.3 | P4: 105.6 | Q4: 105.1 | R4: 106.3 | S4: 105.5 | T4: 106.2 | U4: 100.3 | V4: 105.5 | W4: 104.8 | X4: 104 | Y4: 103.2 | Z4: 103.1 | AA4: 103.6 | AB4: 104.5 | AC4: 103.9 | AD4: 104.6
A5: Rural | B5: 2013 | C5: February | D5: 109.2 | E5: 108.7 | F5: 110.2 | G5: 105.4 | H5: 106.7 | I5: 104 | J5: 102.4 | K5: 105.9 | L5: 105.7 | M5: 103.1 | N5: 105.1 | O5: 107.7 | P5: 106.3 | Q5: 105.6 | R5: 107.1 | S5: 106.3 | T5: 107 | U5: NA | V5: 106.2 | W5: 105.2 | X5: 104.4 | Y5: 103.9 | Z5: 104 | AA5: 104.1 | AB5: 104.6 | AC5: 104.4 | AD5: 105.8
A6: Urban | B6: 2013 | C6: February | D6: 112.9 | E6: 112.9 | F6: 116.9 | G6: 104 | H6: 103.5 | I6: 103.1 | J6: 104.9 | K6: 104.1 | L6: 103.8 | M6: 102.3 | N6: 106 | O6: 109 | P6: 107.2 | Q6: 106 | R6: 106.6 | S6: 105.5 | T6: 106.4 | U6: 100.4 | V6: 105.7 | W6: 105.2 | X6: 104.7 | Y6: 104.4 | Z6: 103.3 | AA6: 103.7 | AB6: 104.3 | AC6: 104.3 | AD6: 104.7
A7: Rural+Urban | B7: 2013 | C7: February | D7: 110.4 | E7: 110.2 | F7: 112.8 | G7: 104.9 | H7: 105.5 | I7: 103.6 | J7: 103.2 | K7: 105.3 | L7: 105.1 | M7: 102.8 | N7: 105.5 | O7: 108.3 | P7: 106.6 | Q7: 105.7 | R7: 106.9 | S7: 106 | T7: 106.8 | U7: 100.4 | V7: 106 | W7: 105.2 | X7: 104.5 | Y7: 104.2 | Z7: 103.6 | AA7: 103.9 | AB7: 104.5 | AC7: 104.4 | AD7: 105.3
A8: Rural | B8: 2013 | C8: March | D8: 110.2 | E8: 108.8 | F8: 109.9 | G8: 105.6 | H8: 106.2 | I8: 105.7 | J8: 101.4 | K8: 105.7 | L8: 105 | M8: 103.3 | N8: 105.6 | O8: 108.2 | P8: 106.6 | Q8: 106.5 | R8: 107.6 | S8: 106.8 | T8: 107.5 | U8: NA | V8: 106.1 | W8: 105.6 | X8: 104.7 | Y8: 104.6 | Z8: 104 | AA8: 104.3 | AB8: 104.3 | AC8: 104.6 | AD8: 106
A9: Urban | B9: 2013 | C9: March | D9: 113.9 | E9: 111.4 | F9: 113.2 | G9: 104.3 | H9: 102.7 | I9: 104.9 | J9: 103.8 | K9: 103.5 | L9: 102.6 | M9: 102.4 | N9: 107 | O9: 109.8 | P9: 107.3 | Q9: 106.8 | R9: 107.2 | S9: 106 | T9: 107 | U9: 100.4 | V9: 106 | W9: 105.7 | X9: 105.2 | Y9: 105.5 | Z9: 103.5 | AA9: 103.8 | AB9: 104.2 | AC9: 104.9 | AD9: 105
A10: Rural+Urban | B10: 2013 | C10: March | D10: 111.4 | E10: 109.7 | F10: 111.2 | G10: 105.1 | H10: 104.9 | I10: 105.3 | J10: 102.2 | K10: 105 | L10: 104.2 | M10: 103 | N10: 106.2 | O10: 108.9 | P10: 106.9 | Q10: 106.6 | R10: 107.4 | S10: 106.5 | T10: 107.3 | U10: 100.4 | V10: 106.1 | W10: 105.6 | X10: 104.9 | Y10: 105.1 | Z10: 103.7 | AA10: 104 | AB10: 104.3 | AC10: 104.7 | AD10: 105.5
A11: Rural | B11: 2013 | C11: April | D11: 110.2 | E11: 109.5 | F11: 106.9 | G11: 106.3 | H11: 105.7 | I11: 108.3 | J11: 103.4 | K11: 105.7 | L11: 104.2 | M11: 103.2 | N11: 106.5 | O11: 108.8 | P11: 107.1 | Q11: 107.1 | R11: 108.1 | S11: 107.4 | T11: 108 | U11: NA | V11: 106.5 | W11: 106.1 | X11: 105.1 | Y11: 104.4 | Z11: 104.5 | AA11: 104.8 | AB11: 102.7 | AC11: 104.6 | AD11: 106.4
A12: Urban | B12: 2013 | C12: April | D12: 114.6 | E12: 113.4 | F12: 106 | G12: 104.7 | H12: 102.1 | I12: 109.5 | J12: 109.7 | K12: 104.6 | L12: 102 | M12: 103.5 | N12: 108.2 | O12: 110.6 | P12: 108.8 | Q12: 108.5 | R12: 107.9 | S12: 106.4 | T12: 107.7 | U12: 100.5 | V12: 106.4 | W12: 106.5 | X12: 105.7 | Y12: 105 | Z12: 104 | AA12: 105.2 | AB12: 103.2 | AC12: 105.1 | AD12: 105.7
A13: Rural+Urban | B13: 2013 | C13: April | D13: 111.6 | E13: 110.9 | F13: 106.6 | G13: 105.7 | H13: 104.4 | I13: 108.9 | J13: 105.5 | K13: 105.3 | L13: 103.5 | M13: 103.3 | N13: 107.2 | O13: 109.6 | P13: 107.7 | Q13: 107.5 | R13: 108 | S13: 107 | T13: 107.9 | U13: 100.5 | V13: 106.5 | W13: 106.3 | X13: 105.3 | Y13: 104.7 | Z13: 104.2 | AA13: 105 | AB13: 102.9 | AC13: 104.8 | AD13: 106.1
A14: Rural | B14: 2013 | C14: May | D14: 110.9 | E14: 109.8 | F14: 105.9 | G14: 107.5 | H14: 105.3 | I14: 108.1 | J14: 107.3 | K14: 106.1 | L14: 103.7 | M14: 104 | N14: 107.4 | O14: 109.9 | P14: 108.1 | Q14: 108.1 | R14: 108.8 | S14: 107.9 | T14: 108.6 | U14: NA | V14: 107.5 | W14: 106.8 | X14: 105.7 | Y14: 104.1 | Z14: 105 | AA14: 105.5 | AB14: 102.1 | AC14: 104.8 | AD14: 107.2
A15: Urban | B15: 2013 | C15: May | D15: 115.4 | E15: 114.2 | F15: 102.7 | G15: 105.5 | H15: 101.5 | I15: 110.6 | J15: 123.7 | K15: 105.2 | L15: 101.9 | M15: 105 | N15: 109.1 | O15: 111.3 | P15: 111.1 | Q15: 109.8 | R15: 108.5 | S15: 106.7 | T15: 108.3 | U15: 100.5 | V15: 107.2 | W15: 107.1 | X15: 106.2 | Y15: 103.9 | Z15: 104.6 | AA15: 105.7 | AB15: 102.6 | AC15: 104.9 | AD15: 106.6
A16: Rural+Urban | B16: 2013 | C16: May | D16: 112.3 | E16: 111.3 | F16: 104.7 | G16: 106.8 | H16: 103.9 | I16: 109.3 | J16: 112.9 | K16: 105.8 | L16: 103.1 | M16: 104.3 | N16: 108.1 | O16: 110.5 | P16: 109.2 | Q16: 108.6 | R16: 108.7 | S16: 107.4 | T16: 108.5 | U16: 100.5 | V16: 107.4 | W16: 106.9 | X16: 105.9 | Y16: 104 | Z16: 104.8 | AA16: 105.6 | AB16: 102.3 | AC16: 104.8 | AD16: 106.9
A17: Rural | B17: 2013 | C17: June | D17: 112.3 | E17: 112.1 | F17: 108.1 | G17: 108.3 | H17: 105.9 | I17: 109.2 | J17: 118 | K17: 106.8 | L17: 104.1 | M17: 105.4 | N17: 108.2 | O17: 111 | P17: 110.6 | Q17: 109 | R17: 109.7 | S17: 108.8 | T17: 109.5 | U17: NA | V17: 108.5 | W17: 107.5 | X17: 106.3 | Y17: 105 | Z17: 105.6 | AA17: 106.5 | AB17: 102.5 | AC17: 105.5 | AD17: 108.9
A18: Urban | B18: 2013 | C18: June | D18: 117 | E18: 120.1 | F18: 112.5 | G18: 107.3 | H18: 101.3 | I18: 112.4 | J18: 143.6 | K18: 105.4 | L18: 101.4 | M18: 106.4 | N18: 110 | O18: 112.2 | P18: 115 | Q18: 110.9 | R18: 109.2 | S18: 107.2 | T18: 108.9 | U18: 106.6 | V18: 108 | W18: 107.7 | X18: 106.5 | Y18: 105.2 | Z18: 105.2 | AA18: 108.1 | AB18: 103.3 | AC18: 106.1 | AD18: 109.7
A19: Rural+Urban | B19: 2013 | C19: June | D19: 113.8 | E19: 114.9 | F19: 109.8 | G19: 107.9 | H19: 104.2 | I19: 110.7 | J19: 126.7 | K19: 106.3 | L19: 103.2 | M19: 105.7 | N19: 109 | O19: 111.6 | P19: 112.2 | Q19: 109.5 | R19: 109.5 | S19: 108.1 | T19: 109.3 | U19: 106.6 | V19: 108.3 | W19: 107.6 | X19: 106.4 | Y19: 105.1 | Z19: 105.4 | AA19: 107.4 | AB19: 102.8 | AC19: 105.8 | AD19: 109.3
A20: Rural | B20: 2013 | C20: July | D20: 113.4 | E20: 114.9 | F20: 110.5 | G20: 109.3 | H20: 106.2 | I20: 110.3 | J20: 129.2 | K20: 107.1 | L20: 104.3 | M20: 106.4 | N20: 109.1 | O20: 112.1 | P20: 113.1 | Q20: 109.8 | R20: 110.5 | S20: 109.5 | T20: 110.3 | U20: NA | V20: 109.5 | W20: 108.3 | X20: 106.9 | Y20: 106.8 | Z20: 106.4 | AA20: 107.8 | AB20: 102.5 | AC20: 106.5 | AD20: 110.7
A21: Urban | B21: 2013 | C21: July | D21: 117.8 | E21: 119.2 | F21: 114 | G21: 108.3 | H21: 101.1 | I21: 113.2 | J21: 160.9 | K21: 105.1 | L21: 101.3 | M21: 107.5 | N21: 110.4 | O21: 113.1 | P21: 117.5 | Q21: 111.7 | R21: 109.8 | S21: 107.8 | T21: 109.5 | U21: 107.7 | V21: 108.6 | W21: 108.1 | X21: 107.1 | Y21: 107.3 | Z21: 105.9 | AA21: 110.1 | AB21: 103.2 | AC21: 107.3 | AD21: 111.4
A22: Rural+Urban | B22: 2013 | C22: July | D22: 114.8 | E22: 116.4 | F22: 111.9 | G22: 108.9 | H22: 104.3 | I22: 111.7 | J22: 140 | K22: 106.4 | L22: 103.3 | M22: 106.8 | N22: 109.6 | O22: 112.6 | P22: 114.7 | Q22: 110.3 | R22: 110.2 | S22: 108.8 | T22: 110 | U22: 107.7 | V22: 109.2 | W22: 108.2 | X22: 107 | Y22: 107.1 | Z22: 106.1 | AA22: 109.1 | AB22: 102.8 | AC22: 106.9 | AD22: 111
A23: Rural | B23: 2013 | C23: August | D23: 114.3 | E23: 115.4 | F23: 111.1 | G23: 110 | H23: 106.4 | I23: 110.8 | J23: 138.9 | K23: 107.4 | L23: 104.1 | M23: 106.9 | N23: 109.7 | O23: 112.6 | P23: 114.9 | Q23: 110.7 | R23: 111.3 | S23: 110.2 | T23: 111.1 | U23: NA | V23: 109.9 | W23: 108.7 | X23: 107.5 | Y23: 107.8 | Z23: 106.8 | AA23: 108.7 | AB23: 105 | AC23: 107.5 | AD23: 112.1
A24: Urban | B24: 2013 | C24: August | D24: 118.3 | E24: 120.4 | F24: 112.7 | G24: 108.9 | H24: 101.1 | I24: 108.7 | J24: 177 | K24: 104.7 | L24: 101 | M24: 108.5 | N24: 110.9 | O24: 114.3 | P24: 119.6 | Q24: 112.4 | R24: 110.6 | S24: 108.3 | T24: 110.2 | U24: 108.9 | V24: 109.3 | W24: 108.7 | X24: 107.6 | Y24: 108.1 | Z24: 106.5 | AA24: 110.8 | AB24: 106 | AC24: 108.3 | AD24: 112.7
A25: Rural+Urban | B25: 2013 | C25: August | D25: 115.6 | E25: 117.2 | F25: 111.7 | G25: 109.6 | H25: 104.5 | I25: 109.8 | J25: 151.8 | K25: 106.5 | L25: 103.1 | M25: 107.4 | N25: 110.2 | O25: 113.4 | P25: 116.6 | Q25: 111.2 | R25: 111 | S25: 109.4 | T25: 110.7 | U25: 108.9 | V25: 109.7 | W25: 108.7 | X25: 107.5 | Y25: 108 | Z25: 106.6 | AA25: 109.9 | AB25: 105.4 | AC25: 107.9 | AD25: 112.4
A26: Rural | B26: 2013 | C26: September | D26: 115.4 | E26: 115.7 | F26: 111.7 | G26: 111 | H26: 107.4 | I26: 110.9 | J26: 154 | K26: 108.1 | L26: 104.2 | M26: 107.9 | N26: 110.4 | O26: 114 | P26: 117.8 | Q26: 111.7 | R26: 112.7 | S26: 111.4 | T26: 112.5 | U26: NA | V26: 111.1 | W26: 109.6 | X26: 108.3 | Y26: 109.3 | Z26: 107.7 | AA26: 109.8 | AB26: 106.7 | AC26: 108.7 | AD26: 114.2
A27: Urban | B27: 2013 | C27: September | D27: 118.6 | E27: 119.1 | F27: 113.2 | G27: 109.6 | H27: 101.7 | I27: 103.2 | J27: 174.3 | K27: 105.1 | L27: 100.8 | M27: 109.1 | N27: 111.1 | O27: 115.4 | P27: 119.2 | Q27: 112.9 | R27: 111.4 | S27: 109 | T27: 111.1 | U27: 109.7 | V27: 109.5 | W27: 109.6 | X27: 107.9 | Y27: 110.4 | Z27: 107.4 | AA27: 111.2 | AB27: 106.9 | AC27: 109.4 | AD27: 113.2
A28: Rural+Urban | B28: 2013 | C28: September | D28: 116.4 | E28: 116.9 | F28: 112.3 | G28: 110.5 | H28: 105.3 | I28: 107.3 | J28: 160.9 | K28: 107.1 | L28: 103.1 | M28: 108.3 | N28: 110.7 | O28: 114.6 | P28: 118.3 | Q28: 112 | R28: 112.2 | S28: 110.4 | T28: 111.9 | U28: 109.7 | V28: 110.5 | W28: 109.6 | X28: 108.1 | Y28: 109.9 | Z28: 107.5 | AA28: 110.6 | AB28: 106.8 | AC28: 109 | AD28: 113.7
A29: Rural | B29: 2013 | C29: October | D29: 116.3 | E29: 115.4 | F29: 112.6 | G29: 111.7 | H29: 107.7 | I29: 113.2 | J29: 164.9 | K29: 108.3 | L29: 103.9 | M29: 108.2 | N29: 111.1 | O29: 114.9 | P29: 119.8 | Q29: 112.2 | R29: 113.6 | S29: 112.3 | T29: 113.4 | U29: NA | V29: 111.6 | W29: 110.4 | X29: 108.9 | Y29: 109.3 | Z29: 108.3 | AA29: 110.2 | AB29: 107.5 | AC29: 109.1 | AD29: 115.5
A30: Urban | B30: 2013 | C30: October | D30: 118.9 | E30: 118.1 | F30: 114.5 | G30: 110.4 | H30: 102.3 | I30: 106.2 | J30: 183.5 | K30: 105.3 | L30: 100.2 | M30: 109.6 | N30: 111.4 | O30: 116 | P30: 120.8 | Q30: 113.5 | R30: 112.5 | S30: 109.7 | T30: 112 | U30: 110.5 | V30: 109.7 | W30: 110.2 | X30: 108.2 | Y30: 109.7 | Z30: 108 | AA30: 111.3 | AB30: 107.3 | AC30: 109.4 | AD30: 114
A31: Rural+Urban | B31: 2013 | C31: October | D31: 117.1 | E31: 116.3 | F31: 113.3 | G31: 111.2 | H31: 105.7 | I31: 109.9 | J31: 171.2 | K31: 107.3 | L31: 102.7 | M31: 108.7 | N31: 111.2 | O31: 115.4 | P31: 120.2 | Q31: 112.5 | R31: 113.2 | S31: 111.2 | T31: 112.8 | U31: 110.5 | V31: 110.9 | W31: 110.3 | X31: 108.6 | Y31: 109.5 | Z31: 108.1 | AA31: 110.8 | AB31: 107.4 | AC31: 109.2 | AD31: 114.8
A32: Rural | B32: 2013 | C32: November | D32: 117.3 | E32: 114.9 | F32: 116.2 | G32: 112.8 | H32: 108.9 | I32: 116.6 | J32: 178.1 | K32: 109.1 | L32: 103.6 | M32: 109 | N32: 111.8 | O32: 116 | P32: 122.5 | Q32: 112.8 | R32: 114.6 | S32: 113.1 | T32: 114.4 | U32: NA | V32: 112.6 | W32: 111.3 | X32: 109.7 | Y32: 109.6 | Z32: 108.7 | AA32: 111 | AB32: 108.2 | AC32: 109.8 | AD32: 117.4
A33: Urban | B33: 2013 | C33: November | D33: 119.8 | E33: 116.3 | F33: 122.6 | G33: 112 | H33: 103.2 | I33: 110 | J33: 192.8 | K33: 106.3 | L33: 99.5 | M33: 110.3 | N33: 111.8 | O33: 117.1 | P33: 122.9 | Q33: 114.1 | R33: 113.5 | S33: 110.3 | T33: 113 | U33: 111.1 | V33: 110 | W33: 110.9 | X33: 108.6 | Y33: 109.5 | Z33: 108.5 | AA33: 111.3 | AB33: 107.9 | AC33: 109.6 | AD33: 115
A34: Rural+Urban | B34: 2013 | C34: November | D34: 118.1 | E34: 115.4 | F34: 118.7 | G34: 112.5 | H34: 106.8 | I34: 113.5 | J34: 183.1 | K34: 108.2 | L34: 102.2 | M34: 109.4 | N34: 111.8 | O34: 116.5 | P34: 122.6 | Q34: 113.1 | R34: 114.2 | S34: 111.9 | T34: 113.8 | U34: 111.1 | V34: 111.6 | W34: 111.1 | X34: 109.3 | Y34: 109.5 | Z34: 108.6 | AA34: 111.2 | AB34: 108.1 | AC34: 109.7 | AD34: 116.3
A35: Rural | B35: 2013 | C35: December | D35: 118.4 | E35: 115.9 | F35: 120.4 | G35: 113.8 | H35: 109.5 | I35: 115.5 | J35: 145.7 | K35: 109.5 | L35: 102.9 | M35: 109.8 | N35: 112.1 | O35: 116.8 | P35: 118.7 | Q35: 113.6 | R35: 115.8 | S35: 114 | T35: 115.5 | U35: NA | V35: 112.8 | W35: 112.1 | X35: 110.1 | Y35: 109.9 | Z35: 109.2 | AA35: 111.6 | AB35: 108.1 | AC35: 110.1 | AD35: 115.5
A36: Urban | B36: 2013 | C36: December | D36: 120.5 | E36: 118.1 | F36: 128.5 | G36: 112.8 | H36: 103.4 | I36: 110.7 | J36: 144.8 | K36: 107.1 | L36: 98.6 | M36: 111.9 | N36: 112.1 | O36: 118.1 | P36: 117.8 | Q36: 115 | R36: 114.2 | S36: 110.9 | T36: 113.7 | U36: 110.7 | V36: 110.4 | W36: 111.3 | X36: 109 | Y36: 109.7 | Z36: 108.9 | AA36: 111.4 | AB36: 107.7 | AC36: 109.8 | AD36: 113.3
A37: Rural+Urban | B37: 2013 | C37: December | D37: 119.1 | E37: 116.7 | F37: 123.5 | G37: 113.4 | H37: 107.3 | I37: 113.3 | J37: 145.4 | K37: 108.7 | L37: 101.5 | M37: 110.5 | N37: 112.1 | O37: 117.4 | P37: 118.4 | Q37: 114 | R37: 115.2 | S37: 112.7 | T37: 114.8 | U37: 110.7 | V37: 111.9 | W37: 111.7 | X37: 109.7 | Y37: 109.8 | Z37: 109 | AA37: 111.5 | AB37: 107.9 | AC37: 110 | AD37: 114.5
A38: Rural | B38: 2014 | C38: January | D38: 118.9 | E38: 117.1 | F38: 120.5 | G38: 114.4 | H38: 109 | I38: 115.5 | J38: 123.9 | K38: 109.6 | L38: 101.8 | M38: 110.2 | N38: 112.4 | O38: 117.3 | P38: 116 | Q38: 114 | R38: 116.5 | S38: 114.5 | T38: 116.2 | U38: NA | V38: 113 | W38: 112.6 | X38: 110.6 | Y38: 110.5 | Z38: 109.6 | AA38: 111.8 | AB38: 108.3 | AC38: 110.6 | AD38: 114.2
A39: Urban | B39: 2014 | C39: January | D39: 121.2 | E39: 122 | F39: 129.9 | G39: 113.6 | H39: 102.9 | I39: 112.1 | J39: 118.9 | K39: 107.5 | L39: 96.9 | M39: 112.7 | N39: 112.1 | O39: 119 | P39: 115.5 | Q39: 115.7 | R39: 114.8 | S39: 111.3 | T39: 114.3 | U39: 111.6 | V39: 111 | W39: 111.9 | X39: 109.7 | Y39: 110.8 | Z39: 109.8 | AA39: 111.5 | AB39: 108 | AC39: 110.5 | AD39: 112.9
A40: Rural+Urban | B40: 2014 | C40: January | D40: 119.6 | E40: 118.8 | F40: 124.1 | G40: 114.1 | H40: 106.8 | I40: 113.9 | J40: 122.2 | K40: 108.9 | L40: 100.2 | M40: 111 | N40: 112.3 | O40: 118.1 | P40: 115.8 | Q40: 114.5 | R40: 115.8 | S40: 113.2 | T40: 115.4 | U40: 111.6 | V40: 112.2 | W40: 112.3 | X40: 110.3 | Y40: 110.7 | Z40: 109.7 | AA40: 111.6 | AB40: 108.2 | AC40: 110.6 | AD40: 113.6
...

Sheet Clean Data
A1: S. No. | B1: Sector | C1: Year | D1: Month | E1: Cereals and products | F1: Meat and fish | G1: Egg | H1: Milk and products | I1: Oils and fats | J1: Fruits | K1: Vegetables | L1: Pulses and products | M1: Sugar and Confectionery | N1: Spices | O1: Non-alcoholic beverages | P1: Prepared meals, snacks, sweets etc. | Q1: Food and beverages | R1: Pan, tobacco and intoxicants | S1: Clothing | T1: Footwear | U1: Clothing and footwear | V1: Housing | W1: Fuel and light | X1: Household goods and services | Y1: Health | Z1: Transport and communication | AA1: Recreation and amusement | AB1: Education | AC1: Personal care and effects | AD1: Miscellaneous | AE1: General index
A2: 1 | B2: Rural | C2: 2013 | D2: January | E2: 107.5 | F2: 106.3 | G2: 108.1 | H2: 104.9 | I2: 106.1 | J2: 103.9 | K2: 101.9 | L2: 106.1 | M2: 106.8 | N2: 103.1 | O2: 104.8 | P2: 106.7 | Q2: 105.5 | R2: 105.1 | S2: 106.5 | T2: 105.8 | U2: 106.4 | V2: =VLOOKUP($A2,'Impute housing Missing Value'!$A$1:$C$125,3,0) -> 100.3 | W2: 105.5 | X2: 104.8 | Y2: 104 | Z2: 103.3 | AA2: 103.4 | AB2: 103.8 | AC2: 104.7 | AD2: 104 | AE2: 105.1
A3: 2 | B3: Urban | C3: 2013 | D3: January | E3: 110.5 | F3: 109.1 | G3: 113 | H3: 103.6 | I3: 103.4 | J3: 102.3 | K3: 102.9 | L3: 105.8 | M3: 105.1 | N3: 101.8 | O3: 105.1 | P3: 107.9 | Q3: 105.9 | R3: 105.2 | S3: 105.9 | T3: 105 | U3: 105.8 | V3: 100.4 | W3: 105.4 | X3: 104.8 | Y3: 104.1 | Z3: 103.2 | AA3: 102.9 | AB3: 103.5 | AC3: 104.3 | AD3: 103.7 | AE3: 104
A4: 3 | B4: Rural+Urban | C4: 2013 | D4: January | E4: 108.4 | F4: 107.3 | G4: 110 | H4: 104.4 | I4: 105.1 | J4: 103.2 | K4: 102.2 | L4: 106 | M4: 106.2 | N4: 102.7 | O4: 104.9 | P4: 107.3 | Q4: 105.6 | R4: 105.1 | S4: 106.3 | T4: 105.5 | U4: 106.2 | V4: 100.4 | W4: 105.5 | X4: 104.8 | Y4: 104 | Z4: 103.2 | AA4: 103.1 | AB4: 103.6 | AC4: 104.5 | AD4: 103.9 | AE4: 104.6
A5: 4 | B5: Rural | C5: 2013 | D5: February | E5: 109.2 | F5: 108.7 | G5: 110.2 | H5: 105.4 | I5: 106.7 | J5: 104 | K5: 102.4 | L5: 105.9 | M5: 105.7 | N5: 103.1 | O5: 105.1 | P5: 107.7 | Q5: 106.3 | R5: 105.6 | S5: 107.1 | T5: 106.3 | U5: 107 | V5: =VLOOKUP($A5,'Impute housing Missing Value'!$A$1:$C$125,3,0) -> 100.4 | W5: 106.2 | X5: 105.2 | Y5: 104.4 | Z5: 103.9 | AA5: 104 | AB5: 104.1 | AC5: 104.6 | AD5: 104.4 | AE5: 105.8
A6: 5 | B6: Urban | C6: 2013 | D6: February | E6: 112.9 | F6: 112.9 | G6: 116.9 | H6: 104 | I6: 103.5 | J6: 103.1 | K6: 104.9 | L6: 104.1 | M6: 103.8 | N6: 102.3 | O6: 106 | P6: 109 | Q6: 107.2 | R6: 106 | S6: 106.6 | T6: 105.5 | U6: 106.4 | V6: 100.4 | W6: 105.7 | X6: 105.2 | Y6: 104.7 | Z6: 104.4 | AA6: 103.3 | AB6: 103.7 | AC6: 104.3 | AD6: 104.3 | AE6: 104.7
A7: 6 | B7: Rural+Urban | C7: 2013 | D7: February | E7: 110.4 | F7: 110.2 | G7: 112.8 | H7: 104.9 | I7: 105.5 | J7: 103.6 | K7: 103.2 | L7: 105.3 | M7: 105.1 | N7: 102.8 | O7: 105.5 | P7: 108.3 | Q7: 106.6 | R7: 105.7 | S7: 106.9 | T7: 106 | U7: 106.8 | V7: 100.4 | W7: 106 | X7: 105.2 | Y7: 104.5 | Z7: 104.2 | AA7: 103.6 | AB7: 103.9 | AC7: 104.5 | AD7: 104.4 | AE7: 105.3
A8: 7 | B8: Rural | C8: 2013 | D8: March | E8: 110.2 | F8: 108.8 | G8: 109.9 | H8: 105.6 | I8: 106.2 | J8: 105.7 | K8: 101.4 | L8: 105.7 | M8: 105 | N8: 103.3 | O8: 105.6 | P8: 108.2 | Q8: 106.6 | R8: 106.5 | S8: 107.6 | T8: 106.8 | U8: 107.5 | V8: =VLOOKUP($A8,'Impute housing Missing Value'!$A$1:$C$125,3,0) -> 100.4 | W8: 106.1 | X8: 105.6 | Y8: 104.7 | Z8: 104.6 | AA8: 104 | AB8: 104.3 | AC8: 104.3 | AD8: 104.6 | AE8: 106
A9: 8 | B9: Urban | C9: 2013 | D9: March | E9: 113.9 | F9: 111.4 | G9: 113.2 | H9: 104.3 | I9: 102.7 | J9: 104.9 | K9: 103.8 | L9: 103.5 | M9: 102.6 | N9: 102.4 | O9: 107 | P9: 109.8 | Q9: 107.3 | R9: 106.8 | S9: 107.2 | T9: 106 | U9: 107 | V9: 100.4 | W9: 106 | X9: 105.7 | Y9: 105.2 | Z9: 105.5 | AA9: 103.5 | AB9: 103.8 | AC9: 104.2 | AD9: 104.9 | AE9: 105
A10: 9 | B10: Rural+Urban | C10: 2013 | D10: March | E10: 111.4 | F10: 109.7 | G10: 111.2 | H10: 105.1 | I10: 104.9 | J10: 105.3 | K10: 102.2 | L10: 105 | M10: 104.2 | N10: 103 | O10: 106.2 | P10: 108.9 | Q10: 106.9 | R10: 106.6 | S10: 107.4 | T10: 106.5 | U10: 107.3 | V10: 100.4 | W10: 106.1 | X10: 105.6 | Y10: 104.9 | Z10: 105.1 | AA10: 103.7 | AB10: 104 | AC10: 104.3 | AD10: 104.7 | AE10: 105.5
A11: 10 | B11: Rural | C11: 2013 | D11: April | E11: 110.2 | F11: 109.5 | G11: 106.9 | H11: 106.3 | I11: 105.7 | J11: 108.3 | K11: 103.4 | L11: 105.7 | M11: 104.2 | N11: 103.2 | O11: 106.5 | P11: 108.8 | Q11: 107.1 | R11: 107.1 | S11: 108.1 | T11: 107.4 | U11: 108 | V11: =VLOOKUP($A11,'Impute housing Missing Value'!$A$1:$C$125,3,0) -> 100.5 | W11: 106.5 | X11: 106.1 | Y11: 105.1 | Z11: 104.4 | AA11: 104.5 | AB11: 104.8 | AC11: 102.7 | AD11: 104.6 | AE11: 106.4
A12: 11 | B12: Urban | C12: 2013 | D12: April | E12: 114.6 | F12: 113.4 | G12: 106 | H12: 104.7 | I12: 102.1 | J12: 109.5 | K12: 109.7 | L12: 104.6 | M12: 102 | N12: 103.5 | O12: 108.2 | P12: 110.6 | Q12: 108.8 | R12: 108.5 | S12: 107.9 | T12: 106.4 | U12: 107.7 | V12: 100.4 | W12: 106.4 | X12: 106.5 | Y12: 105.7 | Z12: 105 | AA12: 104 | AB12: 105.2 | AC12: 103.2 | AD12: 105.1 | AE12: 105.7
A13: 12 | B13: Rural+Urban | C13: 2013 | D13: April | E13: 111.6 | F13: 110.9 | G13: 106.6 | H13: 105.7 | I13: 104.4 | J13: 108.9 | K13: 105.5 | L13: 105.3 | M13: 103.5 | N13: 103.3 | O13: 107.2 | P13: 109.6 | Q13: 107.7 | R13: 107.5 | S13: 108 | T13: 107 | U13: 107.9 | V13: 100.4 | W13: 106.5 | X13: 106.3 | Y13: 105.3 | Z13: 104.7 | AA13: 104.2 | AB13: 105 | AC13: 102.9 | AD13: 104.8 | AE13: 106.1
A14: 13 | B14: Rural | C14: 2013 | D14: May | E14: 110.9 | F14: 109.8 | G14: 105.9 | H14: 107.5 | I14: 105.3 | J14: 108.1 | K14: 107.3 | L14: 106.1 | M14: 103.7 | N14: 104 | O14: 107.4 | P14: 109.9 | Q14: 108.1 | R14: 108.1 | S14: 108.8 | T14: 107.9 | U14: 108.6 | V14: =VLOOKUP($A14,'Impute housing Missing Value'!$A$1:$C$125,3,0) -> 100.5 | W14: 107.5 | X14: 106.8 | Y14: 105.7 | Z14: 104.1 | AA14: 105 | AB14: 105.5 | AC14: 102.1 | AD14: 104.8 | AE14: 107.2
A15: 14 | B15: Urban | C15: 2013 | D15: May | E15: 115.4 | F15: 114.2 | G15: 102.7 | H15: 105.5 | I15: 101.5 | J15: 110.6 | K15: 123.7 | L15: 105.2 | M15: 101.9 | N15: 105 | O15: 109.1 | P15: 111.3 | Q15: 111.1 | R15: 109.8 | S15: 108.5 | T15: 106.7 | U15: 108.3 | V15: 100.4 | W15: 107.2 | X15: 107.1 | Y15: 106.2 | Z15: 103.9 | AA15: 104.6 | AB15: 105.7 | AC15: 102.6 | AD15: 104.9 | AE15: 106.6
A16: 15 | B16: Rural+Urban | C16: 2013 | D16: May | E16: 112.3 | F16: 111.3 | G16: 104.7 | H16: 106.8 | I16: 103.9 | J16: 109.3 | K16: 112.9 | L16: 105.8 | M16: 103.1 | N16: 104.3 | O16: 108.1 | P16: 110.5 | Q16: 109.2 | R16: 108.6 | S16: 108.7 | T16: 107.4 | U16: 108.5 | V16: 100.4 | W16: 107.4 | X16: 106.9 | Y16: 105.9 | Z16: 104 | AA16: 104.8 | AB16: 105.6 | AC16: 102.3 | AD16: 104.8 | AE16: 106.9
A17: 16 | B17: Rural | C17: 2013 | D17: June | E17: 112.3 | F17: 112.1 | G17: 108.1 | H17: 108.3 | I17: 105.9 | J17: 109.2 | K17: 118 | L17: 106.8 | M17: 104.1 | N17: 105.4 | O17: 108.2 | P17: 111 | Q17: 110.6 | R17: 109 | S17: 109.7 | T17: 108.8 | U17: 109.5 | V17: =VLOOKUP($A17,'Impute housing Missing Value'!$A$1:$C$125,3,0) -> 106.6 | W17: 108.5 | X17: 107.5 | Y17: 106.3 | Z17: 105 | AA17: 105.6 | AB17: 106.5 | AC17: 102.5 | AD17: 105.5 | AE17: 108.9
A18: 17 | B18: Urban | C18: 2013 | D18: June | E18: 117 | F18: 120.1 | G18: 112.5 | H18: 107.3 | I18: 101.3 | J18: 112.4 | K18: 143.6 | L18: 105.4 | M18: 101.4 | N18: 106.4 | O18: 110 | P18: 112.2 | Q18: 115 | R18: 110.9 | S18: 109.2 | T18: 107.2 | U18: 108.9 | V18: 100.4 | W18: 108 | X18: 107.7 | Y18: 106.5 | Z18: 105.2 | AA18: 105.2 | AB18: 108.1 | AC18: 103.3 | AD18: 106.1 | AE18: 109.7
A19: 18 | B19: Rural+Urban | C19: 2013 | D19: June | E19: 113.8 | F19: 114.9 | G19: 109.8 | H19: 107.9 | I19: 104.2 | J19: 110.7 | K19: 126.7 | L19: 106.3 | M19: 103.2 | N19: 105.7 | O19: 109 | P19: 111.6 | Q19: 112.2 | R19: 109.5 | S19: 109.5 | T19: 108.1 | U19: 109.3 | V19: 100.4 | W19: 108.3 | X19: 107.6 | Y19: 106.4 | Z19: 105.1 | AA19: 105.4 | AB19: 107.4 | AC19: 102.8 | AD19: 105.8 | AE19: 109.3
A20: 19 | B20: Rural | C20: 2013 | D20: July | E20: 113.4 | F20: 114.9 | G20: 110.5 | H20: 109.3 | I20: 106.2 | J20: 110.3 | K20: 129.2 | L20: 107.1 | M20: 104.3 | N20: 106.4 | O20: 109.1 | P20: 112.1 | Q20: 113.1 | R20: 109.8 | S20: 110.5 | T20: 109.5 | U20: 110.3 | V20: =VLOOKUP($A20,'Impute housing Missing Value'!$A$1:$C$125,3,0) -> 107.7 | W20: 109.5 | X20: 108.3 | Y20: 106.9 | Z20: 106.8 | AA20: 106.4 | AB20: 107.8 | AC20: 102.5 | AD20: 106.5 | AE20: 110.7
A21: 20 | B21: Urban | C21: 2013 | D21: July | E21: 117.8 | F21: 119.2 | G21: 114 | H21: 108.3 | I21: 101.1 | J21: 113.2 | K21: 160.9 | L21: 105.1 | M21: 101.3 | N21: 107.5 | O21: 110.4 | P21: 113.1 | Q21: 117.5 | R21: 111.7 | S21: 109.8 | T21: 107.8 | U21: 109.5 | V21: 100.4 | W21: 108.6 | X21: 108.1 | Y21: 107.1 | Z21: 107.3 | AA21: 105.9 | AB21: 110.1 | AC21: 103.2 | AD21: 107.3 | AE21: 111.4
A22: 21 | B22: Rural+Urban | C22: 2013 | D22: July | E22: 114.8 | F22: 116.4 | G22: 111.9 | H22: 108.9 | I22: 104.3 | J22: 111.7 | K22: 140 | L22: 106.4 | M22: 103.3 | N22: 106.8 | O22: 109.6 | P22: 112.6 | Q22: 114.7 | R22: 110.3 | S22: 110.2 | T22: 108.8 | U22: 110 | V22: 100.4 | W22: 109.2 | X22: 108.2 | Y22: 107 | Z22: 107.1 | AA22: 106.1 | AB22: 109.1 | AC22: 102.8 | AD22: 106.9 | AE22: 111
A23: 22 | B23: Rural | C23: 2013 | D23: August | E23: 114.3 | F23: 115.4 | G23: 111.1 | H23: 110 | I23: 106.4 | J23: 110.8 | K23: 138.9 | L23: 107.4 | M23: 104.1 | N23: 106.9 | O23: 109.7 | P23: 112.6 | Q23: 114.9 | R23: 110.7 | S23: 111.3 | T23: 110.2 | U23: 111.1 | V23: =VLOOKUP($A23,'Impute housing Missing Value'!$A$1:$C$125,3,0) -> 108.9 | W23: 109.9 | X23: 108.7 | Y23: 107.5 | Z23: 107.8 | AA23: 106.8 | AB23: 108.7 | AC23: 105 | AD23: 107.5 | AE23: 112.1
A24: 23 | B24: Urban | C24: 2013 | D24: August | E24: 118.3 | F24: 120.4 | G24: 112.7 | H24: 108.9 | I24: 101.1 | J24: 108.7 | K24: 177 | L24: 104.7 | M24: 101 | N24: 108.5 | O24: 110.9 | P24: 114.3 | Q24: 119.6 | R24: 112.4 | S24: 110.6 | T24: 108.3 | U24: 110.2 | V24: 100.4 | W24: 109.3 | X24: 108.7 | Y24: 107.6 | Z24: 108.1 | AA24: 106.5 | AB24: 110.8 | AC24: 106 | AD24: 108.3 | AE24: 112.7
A25: 24 | B25: Rural+Urban | C25: 2013 | D25: August | E25: 115.6 | F25: 117.2 | G25: 111.7 | H25: 109.6 | I25: 104.5 | J25: 109.8 | K25: 151.8 | L25: 106.5 | M25: 103.1 | N25: 107.4 | O25: 110.2 | P25: 113.4 | Q25: 116.6 | R25: 111.2 | S25: 111 | T25: 109.4 | U25: 110.7 | V25: 100.4 | W25: 109.7 | X25: 108.7 | Y25: 107.5 | Z25: 108 | AA25: 106.6 | AB25: 109.9 | AC25: 105.4 | AD25: 107.9 | AE25: 112.4
A26: 25 | B26: Rural | C26: 2013 | D26: September | E26: 115.4 | F26: 115.7 | G26: 111.7 | H26: 111 | I26: 107.4 | J26: 110.9 | K26: 154 | L26: 108.1 | M26: 104.2 | N26: 107.9 | O26: 110.4 | P26: 114 | Q26: 117.8 | R26: 111.7 | S26: 112.7 | T26: 111.4 | U26: 112.5 | V26: =VLOOKUP($A26,'Impute housing Missing Value'!$A$1:$C$125,3,0) -> 109.7 | W26: 111.1 | X26: 109.6 | Y26: 108.3 | Z26: 109.3 | AA26: 107.7 | AB26: 109.8 | AC26: 106.7 | AD26: 108.7 | AE26: 114.2
A27: 26 | B27: Urban | C27: 2013 | D27: September | E27: 118.6 | F27: 119.1 | G27: 113.2 | H27: 109.6 | I27: 101.7 | J27: 103.2 | K27: 174.3 | L27: 105.1 | M27: 100.8 | N27: 109.1 | O27: 111.1 | P27: 115.4 | Q27: 119.2 | R27: 112.9 | S27: 111.4 | T27: 109 | U27: 111.1 | V27: 100.4 | W27: 109.5 | X27: 109.6 | Y27: 107.9 | Z27: 110.4 | AA27: 107.4 | AB27: 111.2 | AC27: 106.9 | AD27: 109.4 | AE27: 113.2
A28: 27 | B28: Rural+Urban | C28: 2013 | D28: September | E28: 116.4 | F28: 116.9 | G28: 112.3 | H28: 110.5 | I28: 105.3 | J28: 107.3 | K28: 160.9 | L28: 107.1 | M28: 103.1 | N28: 108.3 | O28: 110.7 | P28: 114.6 | Q28: 118.3 | R28: 112 | S28: 112.2 | T28: 110.4 | U28: 111.9 | V28: 100.4 | W28: 110.5 | X28: 109.6 | Y28: 108.1 | Z28: 109.9 | AA28: 107.5 | AB28: 110.6 | AC28: 106.8 | AD28: 109 | AE28: 113.7
A29: 28 | B29: Rural | C29: 2013 | D29: October | E29: 116.3 | F29: 115.4 | G29: 112.6 | H29: 111.7 | I29: 107.7 | J29: 113.2 | K29: 164.9 | L29: 108.3 | M29: 103.9 | N29: 108.2 | O29: 111.1 | P29: 114.9 | Q29: 119.8 | R29: 112.2 | S29: 113.6 | T29: 112.3 | U29: 113.4 | V29: =VLOOKUP($A29,'Impute housing Missing Value'!$A$1:$C$125,3,0) -> 110.5 | W29: 111.6 | X29: 110.4 | Y29: 108.9 | Z29: 109.3 | AA29: 108.3 | AB29: 110.2 | AC29: 107.5 | AD29: 109.1 | AE29: 115.5
A30: 29 | B30: Urban | C30: 2013 | D30: October | E30: 118.9 | F30: 118.1 | G30: 114.5 | H30: 110.4 | I30: 102.3 | J30: 106.2 | K30: 183.5 | L30: 105.3 | M30: 100.2 | N30: 109.6 | O30: 111.4 | P30: 116 | Q30: 120.8 | R30: 113.5 | S30: 112.5 | T30: 109.7 | U30: 112 | V30: 100.4 | W30: 109.7 | X30: 110.2 | Y30: 108.2 | Z30: 109.7 | AA30: 108 | AB30: 111.3 | AC30: 107.3 | AD30: 109.4 | AE30: 114
A31: 30 | B31: Rural+Urban | C31: 2013 | D31: October | E31: 117.1 | F31: 116.3 | G31: 113.3 | H31: 111.2 | I31: 105.7 | J31: 109.9 | K31: 171.2 | L31: 107.3 | M31: 102.7 | N31: 108.7 | O31: 111.2 | P31: 115.4 | Q31: 120.2 | R31: 112.5 | S31: 113.2 | T31: 111.2 | U31: 112.8 | V31: 100.4 | W31: 110.9 | X31: 110.3 | Y31: 108.6 | Z31: 109.5 | AA31: 108.1 | AB31: 110.8 | AC31: 107.4 | AD31: 109.2 | AE31: 114.8
A32: 31 | B32: Rural | C32: 2013 | D32: November | E32: 117.3 | F32: 114.9 | G32: 116.2 | H32: 112.8 | I32: 108.9 | J32: 116.6 | K32: 178.1 | L32: 109.1 | M32: 103.6 | N32: 109 | O32: 111.8 | P32: 116 | Q32: 122.5 | R32: 112.8 | S32: 114.6 | T32: 113.1 | U32: 114.4 | V32: =VLOOKUP($A32,'Impute housing Missing Value'!$A$1:$C$125,3,0) -> 111.1 | W32: 112.6 | X32: 111.3 | Y32: 109.7 | Z32: 109.6 | AA32: 108.7 | AB32: 111 | AC32: 108.2 | AD32: 109.8 | AE32: 117.4
A33: 32 | B33: Urban | C33: 2013 | D33: November | E33: 119.8 | F33: 116.3 | G33: 122.6 | H33: 112 | I33: 103.2 | J33: 110 | K33: 192.8 | L33: 106.3 | M33: 99.5 | N33: 110.3 | O33: 111.8 | P33: 117.1 | Q33: 122.9 | R33: 114.1 | S33: 113.5 | T33: 110.3 | U33: 113 | V33: 100.4 | W33: 110 | X33: 110.9 | Y33: 108.6 | Z33: 109.5 | AA33: 108.5 | AB33: 111.3 | AC33: 107.9 | AD33: 109.6 | AE33: 115
A34: 33 | B34: Rural+Urban | C34: 2013 | D34: November | E34: 118.1 | F34: 115.4 | G34: 118.7 | H34: 112.5 | I34: 106.8 | J34: 113.5 | K34: 183.1 | L34: 108.2 | M34: 102.2 | N34: 109.4 | O34: 111.8 | P34: 116.5 | Q34: 122.6 | R34: 113.1 | S34: 114.2 | T34: 111.9 | U34: 113.8 | V34: 100.4 | W34: 111.6 | X34: 111.1 | Y34: 109.3 | Z34: 109.5 | AA34: 108.6 | AB34: 111.2 | AC34: 108.1 | AD34: 109.7 | AE34: 116.3
A35: 34 | B35: Rural | C35: 2013 | D35: December | E35: 118.4 | F35: 115.9 | G35: 120.4 | H35: 113.8 | I35: 109.5 | J35: 115.5 | K35: 145.7 | L35: 109.5 | M35: 102.9 | N35: 109.8 | O35: 112.1 | P35: 116.8 | Q35: 118.7 | R35: 113.6 | S35: 115.8 | T35: 114 | U35: 115.5 | V35: =VLOOKUP($A35,'Impute housing Missing Value'!$A$1:$C$125,3,0) -> 110.7 | W35: 112.8 | X35: 112.1 | Y35: 110.1 | Z35: 109.9 | AA35: 109.2 | AB35: 111.6 | AC35: 108.1 | AD35: 110.1 | AE35: 115.5
A36: 35 | B36: Urban | C36: 2013 | D36: December | E36: 120.5 | F36: 118.1 | G36: 128.5 | H36: 112.8 | I36: 103.4 | J36: 110.7 | K36: 144.8 | L36: 107.1 | M36: 98.6 | N36: 111.9 | O36: 112.1 | P36: 118.1 | Q36: 117.8 | R36: 115 | S36: 114.2 | T36: 110.9 | U36: 113.7 | V36: 100.4 | W36: 110.4 | X36: 111.3 | Y36: 109 | Z36: 109.7 | AA36: 108.9 | AB36: 111.4 | AC36: 107.7 | AD36: 109.8 | AE36: 113.3
A37: 36 | B37: Rural+Urban | C37: 2013 | D37: December | E37: 119.1 | F37: 116.7 | G37: 123.5 | H37: 113.4 | I37: 107.3 | J37: 113.3 | K37: 145.4 | L37: 108.7 | M37: 101.5 | N37: 110.5 | O37: 112.1 | P37: 117.4 | Q37: 118.4 | R37: 114 | S37: 115.2 | T37: 112.7 | U37: 114.8 | V37: 100.4 | W37: 111.9 | X37: 111.7 | Y37: 109.7 | Z37: 109.8 | AA37: 109 | AB37: 111.5 | AC37: 107.9 | AD37: 110 | AE37: 114.5
A38: 37 | B38: Rural | C38: 2014 | D38: January | E38: 118.9 | F38: 117.1 | G38: 120.5 | H38: 114.4 | I38: 109 | J38: 115.5 | K38: 123.9 | L38: 109.6 | M38: 101.8 | N38: 110.2 | O38: 112.4 | P38: 117.3 | Q38: 116 | R38: 114 | S38: 116.5 | T38: 114.5 | U38: 116.2 | V38: =VLOOKUP($A38,'Impute housing Missing Value'!$A$1:$C$125,3,0) -> 111.6 | W38: 113 | X38: 112.6 | Y38: 110.6 | Z38: 110.5 | AA38: 109.6 | AB38: 111.8 | AC38: 108.3 | AD38: 110.6 | AE38: 114.2
A39: 38 | B39: Urban | C39: 2014 | D39: January | E39: 121.2 | F39: 122 | G39: 129.9 | H39: 113.6 | I39: 102.9 | J39: 112.1 | K39: 118.9 | L39: 107.5 | M39: 96.9 | N39: 112.7 | O39: 112.1 | P39: 119 | Q39: 115.5 | R39: 115.7 | S39: 114.8 | T39: 111.3 | U39: 114.3 | V39: 100.4 | W39: 111 | X39: 111.9 | Y39: 109.7 | Z39: 110.8 | AA39: 109.8 | AB39: 111.5 | AC39: 108 | AD39: 110.5 | AE39: 112.9
A40: 39 | B40: Rural+Urban | C40: 2014 | D40: January | E40: 119.6 | F40: 118.8 | G40: 124.1 | H40: 114.1 | I40: 106.8 | J40: 113.9 | K40: 122.2 | L40: 108.9 | M40: 100.2 | N40: 111 | O40: 112.3 | P40: 118.1 | Q40: 115.8 | R40: 114.5 | S40: 115.8 | T40: 113.2 | U40: 115.4 | V40: 100.4 | W40: 112.2 | X40: 112.3 | Y40: 110.3 | Z40: 110.7 | AA40: 109.7 | AB40: 111.6 | AC40: 108.2 | AD40: 110.6 | AE40: 113.6
...

Sheet Working Data
A1: S. No. | B1: Sector | C1: Year | D1: Month | E1: Cereals and products | F1: Meat and fish | G1: Egg | H1: Milk and products | I1: Oils and fats | J1: Fruits | K1: Vegetables | L1: Pulses and products | M1: Sugar and Confectionery | N1: Spices | O1: Non-alcoholic beverages | P1: Prepared meals, snacks, sweets etc. | Q1: Food and beverages | R1: Pan, tobacco and intoxicants | S1: Clothing | T1: Footwear | U1: Clothing and footwear | V1: Housing | W1: Fuel and light | X1: Household goods and services | Y1: Health | Z1: Transport and communication | AA1: Recreation and amusement | AB1: Education | AC1: Personal care and effects | AD1: Miscellaneous | AE1: General index | AG1: Food Bucket | AH1: Pan, tobacco and intoxicants | AI1: House | AJ1: Clothing and footwear | AK1: Others
A2: 1 | B2: Rural | C2: 2013 | D2: January | E2: 107.5 | F2: 106.3 | G2: 108.1 | H2: 104.9 | I2: 106.1 | J2: 103.9 | K2: 101.9 | L2: 106.1 | M2: 106.8 | N2: 103.1 | O2: 104.8 | P2: 106.7 | Q2: 105.5 | R2: 105.1 | S2: 106.5 | T2: 105.8 | U2: 106.4 | V2: =VLOOKUP($A2,'Impute housing Missing Value'!$A$1:$C$125,3,0) -> 100.3 | W2: 105.5 | X2: 104.8 | Y2: 104 | Z2: 103.3 | AA2: 103.4 | AB2: 103.8 | AC2: 104.7 | AD2: 104 | AE2: 105.1 | AG2: =AVERAGE(E2:Q2) -> 105.51538 | AH2: 105.1 | AI2: =AVERAGE(V2:X2) -> 103.53333 | AJ2: =AVERAGE(S2:U2) -> 106.23333 | AK2: =AVERAGE(Y2:AD2) -> 103.86667
A3: 2 | B3: Urban | C3: 2013 | D3: January | E3: 110.5 | F3: 109.1 | G3: 113 | H3: 103.6 | I3: 103.4 | J3: 102.3 | K3: 102.9 | L3: 105.8 | M3: 105.1 | N3: 101.8 | O3: 105.1 | P3: 107.9 | Q3: 105.9 | R3: 105.2 | S3: 105.9 | T3: 105 | U3: 105.8 | V3: 100.4 | W3: 105.4 | X3: 104.8 | Y3: 104.1 | Z3: 103.2 | AA3: 102.9 | AB3: 103.5 | AC3: 104.3 | AD3: 103.7 | AE3: 104 | AG3: =AVERAGE(E3:Q3) -> 105.87692 | AH3: 105.2 | AI3: =AVERAGE(V3:X3) -> 103.53333 | AJ3: =AVERAGE(S3:U3) -> 105.56667 | AK3: =AVERAGE(Y3:AD3) -> 103.61667
A4: 3 | B4: Rural+Urban | C4: 2013 | D4: January | E4: 108.4 | F4: 107.3 | G4: 110 | H4: 104.4 | I4: 105.1 | J4: 103.2 | K4: 102.2 | L4: 106 | M4: 106.2 | N4: 102.7 | O4: 104.9 | P4: 107.3 | Q4: 105.6 | R4: 105.1 | S4: 106.3 | T4: 105.5 | U4: 106.2 | V4: 100.4 | W4: 105.5 | X4: 104.8 | Y4: 104 | Z4: 103.2 | AA4: 103.1 | AB4: 103.6 | AC4: 104.5 | AD4: 103.9 | AE4: 104.6 | AG4: =AVERAGE(E4:Q4) -> 105.63846 | AH4: 105.1 | AI4: =AVERAGE(V4:X4) -> 103.56667 | AJ4: =AVERAGE(S4:U4) -> 106 | AK4: =AVERAGE(Y4:AD4) -> 103.71667
A5: 4 | B5: Rural | C5: 2013 | D5: February | E5: 109.2 | F5: 108.7 | G5: 110.2 | H5: 105.4 | I5: 106.7 | J5: 104 | K5: 102.4 | L5: 105.9 | M5: 105.7 | N5: 103.1 | O5: 105.1 | P5: 107.7 | Q5: 106.3 | R5: 105.6 | S5: 107.1 | T5: 106.3 | U5: 107 | V5: =VLOOKUP($A5,'Impute housing Missing Value'!$A$1:$C$125,3,0) -> 100.4 | W5: 106.2 | X5: 105.2 | Y5: 104.4 | Z5: 103.9 | AA5: 104 | AB5: 104.1 | AC5: 104.6 | AD5: 104.4 | AE5: 105.8 | AG5: =AVERAGE(E5:Q5) -> 106.18462 | AH5: 105.6 | AI5: =AVERAGE(V5:X5) -> 103.93333 | AJ5: =AVERAGE(S5:U5) -> 106.8 | AK5: =AVERAGE(Y5:AD5) -> 104.23333
A6: 5 | B6: Urban | C6: 2013 | D6: February | E6: 112.9 | F6: 112.9 | G6: 116.9 | H6: 104 | I6: 103.5 | J6: 103.1 | K6: 104.9 | L6: 104.1 | M6: 103.8 | N6: 102.3 | O6: 106 | P6: 109 | Q6: 107.2 | R6: 106 | S6: 106.6 | T6: 105.5 | U6: 106.4 | V6: 100.4 | W6: 105.7 | X6: 105.2 | Y6: 104.7 | Z6: 104.4 | AA6: 103.3 | AB6: 103.7 | AC6: 104.3 | AD6: 104.3 | AE6: 104.7 | AG6: =AVERAGE(E6:Q6) -> 106.96923 | AH6: 106 | AI6: =AVERAGE(V6:X6) -> 103.76667 | AJ6: =AVERAGE(S6:U6) -> 106.16667 | AK6: =AVERAGE(Y6:AD6) -> 104.11667
A7: 6 | B7: Rural+Urban | C7: 2013 | D7: February | E7: 110.4 | F7: 110.2 | G7: 112.8 | H7: 104.9 | I7: 105.5 | J7: 103.6 | K7: 103.2 | L7: 105.3 | M7: 105.1 | N7: 102.8 | O7: 105.5 | P7: 108.3 | Q7: 106.6 | R7: 105.7 | S7: 106.9 | T7: 106 | U7: 106.8 | V7: 100.4 | W7: 106 | X7: 105.2 | Y7: 104.5 | Z7: 104.2 | AA7: 103.6 | AB7: 103.9 | AC7: 104.5 | AD7: 104.4 | AE7: 105.3 | AG7: =AVERAGE(E7:Q7) -> 106.47692 | AH7: 105.7 | AI7: =AVERAGE(V7:X7) -> 103.86667 | AJ7: =AVERAGE(S7:U7) -> 106.56667 | AK7: =AVERAGE(Y7:AD7) -> 104.18333
A8: 7 | B8: Rural | C8: 2013 | D8: March | E8: 110.2 | F8: 108.8 | G8: 109.9 | H8: 105.6 | I8: 106.2 | J8: 105.7 | K8: 101.4 | L8: 105.7 | M8: 105 | N8: 103.3 | O8: 105.6 | P8: 108.2 | Q8: 106.6 | R8: 106.5 | S8: 107.6 | T8: 106.8 | U8: 107.5 | V8: =VLOOKUP($A8,'Impute housing Missing Value'!$A$1:$C$125,3,0) -> 100.4 | W8: 106.1 | X8: 105.6 | Y8: 104.7 | Z8: 104.6 | AA8: 104 | AB8: 104.3 | AC8: 104.3 | AD8: 104.6 | AE8: 106 | AG8: =AVERAGE(E8:Q8) -> 106.32308 | AH8: 106.5 | AI8: =AVERAGE(V8:X8) -> 104.03333 | AJ8: =AVERAGE(S8:U8) -> 107.3 | AK8: =AVERAGE(Y8:AD8) -> 104.41667
A9: 8 | B9: Urban | C9: 2013 | D9: March | E9: 113.9 | F9: 111.4 | G9: 113.2 | H9: 104.3 | I9: 102.7 | J9: 104.9 | K9: 103.8 | L9: 103.5 | M9: 102.6 | N9: 102.4 | O9: 107 | P9: 109.8 | Q9: 107.3 | R9: 106.8 | S9: 107.2 | T9: 106 | U9: 107 | V9: 100.4 | W9: 106 | X9: 105.7 | Y9: 105.2 | Z9: 105.5 | AA9: 103.5 | AB9: 103.8 | AC9: 104.2 | AD9: 104.9 | AE9: 105 | AG9: =AVERAGE(E9:Q9) -> 106.67692 | AH9: 106.8 | AI9: =AVERAGE(V9:X9) -> 104.03333 | AJ9: =AVERAGE(S9:U9) -> 106.73333 | AK9: =AVERAGE(Y9:AD9) -> 104.51667
A10: 9 | B10: Rural+Urban | C10: 2013 | D10: March | E10: 111.4 | F10: 109.7 | G10: 111.2 | H10: 105.1 | I10: 104.9 | J10: 105.3 | K10: 102.2 | L10: 105 | M10: 104.2 | N10: 103 | O10: 106.2 | P10: 108.9 | Q10: 106.9 | R10: 106.6 | S10: 107.4 | T10: 106.5 | U10: 107.3 | V10: 100.4 | W10: 106.1 | X10: 105.6 | Y10: 104.9 | Z10: 105.1 | AA10: 103.7 | AB10: 104 | AC10: 104.3 | AD10: 104.7 | AE10: 105.5 | AG10: =AVERAGE(E10:Q10) -> 106.46154 | AH10: 106.6 | AI10: =AVERAGE(V10:X10) -> 104.03333 | AJ10: =AVERAGE(S10:U10) -> 107.06667 | AK10: =AVERAGE(Y10:AD10) -> 104.45
A11: 10 | B11: Rural | C11: 2013 | D11: April | E11: 110.2 | F11: 109.5 | G11: 106.9 | H11: 106.3 | I11: 105.7 | J11: 108.3 | K11: 103.4 | L11: 105.7 | M11: 104.2 | N11: 103.2 | O11: 106.5 | P11: 108.8 | Q11: 107.1 | R11: 107.1 | S11: 108.1 | T11: 107.4 | U11: 108 | V11: =VLOOKUP($A11,'Impute housing Missing Value'!$A$1:$C$125,3,0) -> 100.5 | W11: 106.5 | X11: 106.1 | Y11: 105.1 | Z11: 104.4 | AA11: 104.5 | AB11: 104.8 | AC11: 102.7 | AD11: 104.6 | AE11: 106.4 | AG11: =AVERAGE(E11:Q11) -> 106.6 | AH11: 107.1 | AI11: =AVERAGE(V11:X11) -> 104.36667 | AJ11: =AVERAGE(S11:U11) -> 107.83333 | AK11: =AVERAGE(Y11:AD11) -> 104.35
A12: 11 | B12: Urban | C12: 2013 | D12: April | E12: 114.6 | F12: 113.4 | G12: 106 | H12: 104.7 | I12: 102.1 | J12: 109.5 | K12: 109.7 | L12: 104.6 | M12: 102 | N12: 103.5 | O12: 108.2 | P12: 110.6 | Q12: 108.8 | R12: 108.5 | S12: 107.9 | T12: 106.4 | U12: 107.7 | V12: 100.4 | W12: 106.4 | X12: 106.5 | Y12: 105.7 | Z12: 105 | AA12: 104 | AB12: 105.2 | AC12: 103.2 | AD12: 105.1 | AE12: 105.7 | AG12: =AVERAGE(E12:Q12) -> 107.51538 | AH12: 108.5 | AI12: =AVERAGE(V12:X12) -> 104.43333 | AJ12: =AVERAGE(S12:U12) -> 107.33333 | AK12: =AVERAGE(Y12:AD12) -> 104.7
A13: 12 | B13: Rural+Urban | C13: 2013 | D13: April | E13: 111.6 | F13: 110.9 | G13: 106.6 | H13: 105.7 | I13: 104.4 | J13: 108.9 | K13: 105.5 | L13: 105.3 | M13: 103.5 | N13: 103.3 | O13: 107.2 | P13: 109.6 | Q13: 107.7 | R13: 107.5 | S13: 108 | T13: 107 | U13: 107.9 | V13: 100.4 | W13: 106.5 | X13: 106.3 | Y13: 105.3 | Z13: 104.7 | AA13: 104.2 | AB13: 105 | AC13: 102.9 | AD13: 104.8 | AE13: 106.1 | AG13: =AVERAGE(E13:Q13) -> 106.93846 | AH13: 107.5 | AI13: =AVERAGE(V13:X13) -> 104.4 | AJ13: =AVERAGE(S13:U13) -> 107.63333 | AK13: =AVERAGE(Y13:AD13) -> 104.48333
A14: 13 | B14: Rural | C14: 2013 | D14: May | E14: 110.9 | F14: 109.8 | G14: 105.9 | H14: 107.5 | I14: 105.3 | J14: 108.1 | K14: 107.3 | L14: 106.1 | M14: 103.7 | N14: 104 | O14: 107.4 | P14: 109.9 | Q14: 108.1 | R14: 108.1 | S14: 108.8 | T14: 107.9 | U14: 108.6 | V14: =VLOOKUP($A14,'Impute housing Missing Value'!$A$1:$C$125,3,0) -> 100.5 | W14: 107.5 | X14: 106.8 | Y14: 105.7 | Z14: 104.1 | AA14: 105 | AB14: 105.5 | AC14: 102.1 | AD14: 104.8 | AE14: 107.2 | AG14: =AVERAGE(E14:Q14) -> 107.23077 | AH14: 108.1 | AI14: =AVERAGE(V14:X14) -> 104.93333 | AJ14: =AVERAGE(S14:U14) -> 108.43333 | AK14: =AVERAGE(Y14:AD14) -> 104.53333
A15: 14 | B15: Urban | C15: 2013 | D15: May | E15: 115.4 | F15: 114.2 | G15: 102.7 | H15: 105.5 | I15: 101.5 | J15: 110.6 | K15: 123.7 | L15: 105.2 | M15: 101.9 | N15: 105 | O15: 109.1 | P15: 111.3 | Q15: 111.1 | R15: 109.8 | S15: 108.5 | T15: 106.7 | U15: 108.3 | V15: 100.4 | W15: 107.2 | X15: 107.1 | Y15: 106.2 | Z15: 103.9 | AA15: 104.6 | AB15: 105.7 | AC15: 102.6 | AD15: 104.9 | AE15: 106.6 | AG15: =AVERAGE(E15:Q15) -> 109.01538 | AH15: 109.8 | AI15: =AVERAGE(V15:X15) -> 104.9 | AJ15: =AVERAGE(S15:U15) -> 107.83333 | AK15: =AVERAGE(Y15:AD15) -> 104.65
A16: 15 | B16: Rural+Urban | C16: 2013 | D16: May | E16: 112.3 | F16: 111.3 | G16: 104.7 | H16: 106.8 | I16: 103.9 | J16: 109.3 | K16: 112.9 | L16: 105.8 | M16: 103.1 | N16: 104.3 | O16: 108.1 | P16: 110.5 | Q16: 109.2 | R16: 108.6 | S16: 108.7 | T16: 107.4 | U16: 108.5 | V16: 100.4 | W16: 107.4 | X16: 106.9 | Y16: 105.9 | Z16: 104 | AA16: 104.8 | AB16: 105.6 | AC16: 102.3 | AD16: 104.8 | AE16: 106.9 | AG16: =AVERAGE(E16:Q16) -> 107.86154 | AH16: 108.6 | AI16: =AVERAGE(V16:X16) -> 104.9 | AJ16: =AVERAGE(S16:U16) -> 108.2 | AK16: =AVERAGE(Y16:AD16) -> 104.56667
A17: 16 | B17: Rural | C17: 2013 | D17: June | E17: 112.3 | F17: 112.1 | G17: 108.1 | H17: 108.3 | I17: 105.9 | J17: 109.2 | K17: 118 | L17: 106.8 | M17: 104.1 | N17: 105.4 | O17: 108.2 | P17: 111 | Q17: 110.6 | R17: 109 | S17: 109.7 | T17: 108.8 | U17: 109.5 | V17: =VLOOKUP($A17,'Impute housing Missing Value'!$A$1:$C$125,3,0) -> 106.6 | W17: 108.5 | X17: 107.5 | Y17: 106.3 | Z17: 105 | AA17: 105.6 | AB17: 106.5 | AC17: 102.5 | AD17: 105.5 | AE17: 108.9 | AG17: =AVERAGE(E17:Q17) -> 109.23077 | AH17: 109 | AI17: =AVERAGE(V17:X17) -> 107.53333 | AJ17: =AVERAGE(S17:U17) -> 109.33333 | AK17: =AVERAGE(Y17:AD17) -> 105.23333
A18: 17 | B18: Urban | C18: 2013 | D18: June | E18: 117 | F18: 120.1 | G18: 112.5 | H18: 107.3 | I18: 101.3 | J18: 112.4 | K18: 143.6 | L18: 105.4 | M18: 101.4 | N18: 106.4 | O18: 110 | P18: 112.2 | Q18: 115 | R18: 110.9 | S18: 109.2 | T18: 107.2 | U18: 108.9 | V18: 100.4 | W18: 108 | X18: 107.7 | Y18: 106.5 | Z18: 105.2 | AA18: 105.2 | AB18: 108.1 | AC18: 103.3 | AD18: 106.1 | AE18: 109.7 | AG18: =AVERAGE(E18:Q18) -> 112.66154 | AH18: 110.9 | AI18: =AVERAGE(V18:X18) -> 105.36667 | AJ18: =AVERAGE(S18:U18) -> 108.43333 | AK18: =AVERAGE(Y18:AD18) -> 105.73333
A19: 18 | B19: Rural+Urban | C19: 2013 | D19: June | E19: 113.8 | F19: 114.9 | G19: 109.8 | H19: 107.9 | I19: 104.2 | J19: 110.7 | K19: 126.7 | L19: 106.3 | M19: 103.2 | N19: 105.7 | O19: 109 | P19: 111.6 | Q19: 112.2 | R19: 109.5 | S19: 109.5 | T19: 108.1 | U19: 109.3 | V19: 100.4 | W19: 108.3 | X19: 107.6 | Y19: 106.4 | Z19: 105.1 | AA19: 105.4 | AB19: 107.4 | AC19: 102.8 | AD19: 105.8 | AE19: 109.3 | AG19: =AVERAGE(E19:Q19) -> 110.46154 | AH19: 109.5 | AI19: =AVERAGE(V19:X19) -> 105.43333 | AJ19: =AVERAGE(S19:U19) -> 108.96667 | AK19: =AVERAGE(Y19:AD19) -> 105.48333
A20: 19 | B20: Rural | C20: 2013 | D20: July | E20: 113.4 | F20: 114.9 | G20: 110.5 | H20: 109.3 | I20: 106.2 | J20: 110.3 | K20: 129.2 | L20: 107.1 | M20: 104.3 | N20: 106.4 | O20: 109.1 | P20: 112.1 | Q20: 113.1 | R20: 109.8 | S20: 110.5 | T20: 109.5 | U20: 110.3 | V20: =VLOOKUP($A20,'Impute housing Missing Value'!$A$1:$C$125,3,0) -> 107.7 | W20: 109.5 | X20: 108.3 | Y20: 106.9 | Z20: 106.8 | AA20: 106.4 | AB20: 107.8 | AC20: 102.5 | AD20: 106.5 | AE20: 110.7 | AG20: =AVERAGE(E20:Q20) -> 111.22308 | AH20: 109.8 | AI20: =AVERAGE(V20:X20) -> 108.5 | AJ20: =AVERAGE(S20:U20) -> 110.1 | AK20: =AVERAGE(Y20:AD20) -> 106.15
A21: 20 | B21: Urban | C21: 2013 | D21: July | E21: 117.8 | F21: 119.2 | G21: 114 | H21: 108.3 | I21: 101.1 | J21: 113.2 | K21: 160.9 | L21: 105.1 | M21: 101.3 | N21: 107.5 | O21: 110.4 | P21: 113.1 | Q21: 117.5 | R21: 111.7 | S21: 109.8 | T21: 107.8 | U21: 109.5 | V21: 100.4 | W21: 108.6 | X21: 108.1 | Y21: 107.1 | Z21: 107.3 | AA21: 105.9 | AB21: 110.1 | AC21: 103.2 | AD21: 107.3 | AE21: 111.4 | AG21: =AVERAGE(E21:Q21) -> 114.56923 | AH21: 111.7 | AI21: =AVERAGE(V21:X21) -> 105.7 | AJ21: =AVERAGE(S21:U21) -> 109.03333 | AK21: =AVERAGE(Y21:AD21) -> 106.81667
A22: 21 | B22: Rural+Urban | C22: 2013 | D22: July | E22: 114.8 | F22: 116.4 | G22: 111.9 | H22: 108.9 | I22: 104.3 | J22: 111.7 | K22: 140 | L22: 106.4 | M22: 103.3 | N22: 106.8 | O22: 109.6 | P22: 112.6 | Q22: 114.7 | R22: 110.3 | S22: 110.2 | T22: 108.8 | U22: 110 | V22: 100.4 | W22: 109.2 | X22: 108.2 | Y22: 107 | Z22: 107.1 | AA22: 106.1 | AB22: 109.1 | AC22: 102.8 | AD22: 106.9 | AE22: 111 | AG22: =AVERAGE(E22:Q22) -> 112.41538 | AH22: 110.3 | AI22: =AVERAGE(V22:X22) -> 105.93333 | AJ22: =AVERAGE(S22:U22) -> 109.66667 | AK22: =AVERAGE(Y22:AD22) -> 106.5
A23: 22 | B23: Rural | C23: 2013 | D23: August | E23: 114.3 | F23: 115.4 | G23: 111.1 | H23: 110 | I23: 106.4 | J23: 110.8 | K23: 138.9 | L23: 107.4 | M23: 104.1 | N23: 106.9 | O23: 109.7 | P23: 112.6 | Q23: 114.9 | R23: 110.7 | S23: 111.3 | T23: 110.2 | U23: 111.1 | V23: =VLOOKUP($A23,'Impute housing Missing Value'!$A$1:$C$125,3,0) -> 108.9 | W23: 109.9 | X23: 108.7 | Y23: 107.5 | Z23: 107.8 | AA23: 106.8 | AB23: 108.7 | AC23: 105 | AD23: 107.5 | AE23: 112.1 | AG23: =AVERAGE(E23:Q23) -> 112.5 | AH23: 110.7 | AI23: =AVERAGE(V23:X23) -> 109.16667 | AJ23: =AVERAGE(S23:U23) -> 110.86667 | AK23: =AVERAGE(Y23:AD23) -> 107.21667
A24: 23 | B24: Urban | C24: 2013 | D24: August | E24: 118.3 | F24: 120.4 | G24: 112.7 | H24: 108.9 | I24: 101.1 | J24: 108.7 | K24: 177 | L24: 104.7 | M24: 101 | N24: 108.5 | O24: 110.9 | P24: 114.3 | Q24: 119.6 | R24: 112.4 | S24: 110.6 | T24: 108.3 | U24: 110.2 | V24: 100.4 | W24: 109.3 | X24: 108.7 | Y24: 107.6 | Z24: 108.1 | AA24: 106.5 | AB24: 110.8 | AC24: 106 | AD24: 108.3 | AE24: 112.7 | AG24: =AVERAGE(E24:Q24) -> 115.85385 | AH24: 112.4 | AI24: =AVERAGE(V24:X24) -> 106.13333 | AJ24: =AVERAGE(S24:U24) -> 109.7 | AK24: =AVERAGE(Y24:AD24) -> 107.88333
A25: 24 | B25: Rural+Urban | C25: 2013 | D25: August | E25: 115.6 | F25: 117.2 | G25: 111.7 | H25: 109.6 | I25: 104.5 | J25: 109.8 | K25: 151.8 | L25: 106.5 | M25: 103.1 | N25: 107.4 | O25: 110.2 | P25: 113.4 | Q25: 116.6 | R25: 111.2 | S25: 111 | T25: 109.4 | U25: 110.7 | V25: 100.4 | W25: 109.7 | X25: 108.7 | Y25: 107.5 | Z25: 108 | AA25: 106.6 | AB25: 109.9 | AC25: 105.4 | AD25: 107.9 | AE25: 112.4 | AG25: =AVERAGE(E25:Q25) -> 113.64615 | AH25: 111.2 | AI25: =AVERAGE(V25:X25) -> 106.26667 | AJ25: =AVERAGE(S25:U25) -> 110.36667 | AK25: =AVERAGE(Y25:AD25) -> 107.55
A26: 25 | B26: Rural | C26: 2013 | D26: September | E26: 115.4 | F26: 115.7 | G26: 111.7 | H26: 111 | I26: 107.4 | J26: 110.9 | K26: 154 | L26: 108.1 | M26: 104.2 | N26: 107.9 | O26: 110.4 | P26: 114 | Q26: 117.8 | R26: 111.7 | S26: 112.7 | T26: 111.4 | U26: 112.5 | V26: =VLOOKUP($A26,'Impute housing Missing Value'!$A$1:$C$125,3,0) -> 109.7 | W26: 111.1 | X26: 109.6 | Y26: 108.3 | Z26: 109.3 | AA26: 107.7 | AB26: 109.8 | AC26: 106.7 | AD26: 108.7 | AE26: 114.2 | AG26: =AVERAGE(E26:Q26) -> 114.5 | AH26: 111.7 | AI26: =AVERAGE(V26:X26) -> 110.13333 | AJ26: =AVERAGE(S26:U26) -> 112.2 | AK26: =AVERAGE(Y26:AD26) -> 108.41667
A27: 26 | B27: Urban | C27: 2013 | D27: September | E27: 118.6 | F27: 119.1 | G27: 113.2 | H27: 109.6 | I27: 101.7 | J27: 103.2 | K27: 174.3 | L27: 105.1 | M27: 100.8 | N27: 109.1 | O27: 111.1 | P27: 115.4 | Q27: 119.2 | R27: 112.9 | S27: 111.4 | T27: 109 | U27: 111.1 | V27: 100.4 | W27: 109.5 | X27: 109.6 | Y27: 107.9 | Z27: 110.4 | AA27: 107.4 | AB27: 111.2 | AC27: 106.9 | AD27: 109.4 | AE27: 113.2 | AG27: =AVERAGE(E27:Q27) -> 115.41538 | AH27: 112.9 | AI27: =AVERAGE(V27:X27) -> 106.5 | AJ27: =AVERAGE(S27:U27) -> 110.5 | AK27: =AVERAGE(Y27:AD27) -> 108.86667
A28: 27 | B28: Rural+Urban | C28: 2013 | D28: September | E28: 116.4 | F28: 116.9 | G28: 112.3 | H28: 110.5 | I28: 105.3 | J28: 107.3 | K28: 160.9 | L28: 107.1 | M28: 103.1 | N28: 108.3 | O28: 110.7 | P28: 114.6 | Q28: 118.3 | R28: 112 | S28: 112.2 | T28: 110.4 | U28: 111.9 | V28: 100.4 | W28: 110.5 | X28: 109.6 | Y28: 108.1 | Z28: 109.9 | AA28: 107.5 | AB28: 110.6 | AC28: 106.8 | AD28: 109 | AE28: 113.7 | AG28: =AVERAGE(E28:Q28) -> 114.74615 | AH28: 112 | AI28: =AVERAGE(V28:X28) -> 106.83333 | AJ28: =AVERAGE(S28:U28) -> 111.5 | AK28: =AVERAGE(Y28:AD28) -> 108.65
A29: 28 | B29: Rural | C29: 2013 | D29: October | E29: 116.3 | F29: 115.4 | G29: 112.6 | H29: 111.7 | I29: 107.7 | J29: 113.2 | K29: 164.9 | L29: 108.3 | M29: 103.9 | N29: 108.2 | O29: 111.1 | P29: 114.9 | Q29: 119.8 | R29: 112.2 | S29: 113.6 | T29: 112.3 | U29: 113.4 | V29: =VLOOKUP($A29,'Impute housing Missing Value'!$A$1:$C$125,3,0) -> 110.5 | W29: 111.6 | X29: 110.4 | Y29: 108.9 | Z29: 109.3 | AA29: 108.3 | AB29: 110.2 | AC29: 107.5 | AD29: 109.1 | AE29: 115.5 | AG29: =AVERAGE(E29:Q29) -> 116 | AH29: 112.2 | AI29: =AVERAGE(V29:X29) -> 110.83333 | AJ29: =AVERAGE(S29:U29) -> 113.1 | AK29: =AVERAGE(Y29:AD29) -> 108.88333
A30: 29 | B30: Urban | C30: 2013 | D30: October | E30: 118.9 | F30: 118.1 | G30: 114.5 | H30: 110.4 | I30: 102.3 | J30: 106.2 | K30: 183.5 | L30: 105.3 | M30: 100.2 | N30: 109.6 | O30: 111.4 | P30: 116 | Q30: 120.8 | R30: 113.5 | S30: 112.5 | T30: 109.7 | U30: 112 | V30: 100.4 | W30: 109.7 | X30: 110.2 | Y30: 108.2 | Z30: 109.7 | AA30: 108 | AB30: 111.3 | AC30: 107.3 | AD30: 109.4 | AE30: 114 | AG30: =AVERAGE(E30:Q30) -> 116.70769 | AH30: 113.5 | AI30: =AVERAGE(V30:X30) -> 106.76667 | AJ30: =AVERAGE(S30:U30) -> 111.4 | AK30: =AVERAGE(Y30:AD30) -> 108.98333
A31: 30 | B31: Rural+Urban | C31: 2013 | D31: October | E31: 117.1 | F31: 116.3 | G31: 113.3 | H31: 111.2 | I31: 105.7 | J31: 109.9 | K31: 171.2 | L31: 107.3 | M31: 102.7 | N31: 108.7 | O31: 111.2 | P31: 115.4 | Q31: 120.2 | R31: 112.5 | S31: 113.2 | T31: 111.2 | U31: 112.8 | V31: 100.4 | W31: 110.9 | X31: 110.3 | Y31: 108.6 | Z31: 109.5 | AA31: 108.1 | AB31: 110.8 | AC31: 107.4 | AD31: 109.2 | AE31: 114.8 | AG31: =AVERAGE(E31:Q31) -> 116.16923 | AH31: 112.5 | AI31: =AVERAGE(V31:X31) -> 107.2 | AJ31: =AVERAGE(S31:U31) -> 112.4 | AK31: =AVERAGE(Y31:AD31) -> 108.93333
A32: 31 | B32: Rural | C32: 2013 | D32: November | E32: 117.3 | F32: 114.9 | G32: 116.2 | H32: 112.8 | I32: 108.9 | J32: 116.6 | K32: 178.1 | L32: 109.1 | M32: 103.6 | N32: 109 | O32: 111.8 | P32: 116 | Q32: 122.5 | R32: 112.8 | S32: 114.6 | T32: 113.1 | U32: 114.4 | V32: =VLOOKUP($A32,'Impute housing Missing Value'!$A$1:$C$125,3,0) -> 111.1 | W32: 112.6 | X32: 111.3 | Y32: 109.7 | Z32: 109.6 | AA32: 108.7 | AB32: 111 | AC32: 108.2 | AD32: 109.8 | AE32: 117.4 | AG32: =AVERAGE(E32:Q32) -> 118.21538 | AH32: 112.8 | AI32: =AVERAGE(V32:X32) -> 111.66667 | AJ32: =AVERAGE(S32:U32) -> 114.03333 | AK32: =AVERAGE(Y32:AD32) -> 109.5
A33: 32 | B33: Urban | C33: 2013 | D33: November | E33: 119.8 | F33: 116.3 | G33: 122.6 | H33: 112 | I33: 103.2 | J33: 110 | K33: 192.8 | L33: 106.3 | M33: 99.5 | N33: 110.3 | O33: 111.8 | P33: 117.1 | Q33: 122.9 | R33: 114.1 | S33: 113.5 | T33: 110.3 | U33: 113 | V33: 100.4 | W33: 110 | X33: 110.9 | Y33: 108.6 | Z33: 109.5 | AA33: 108.5 | AB33: 111.3 | AC33: 107.9 | AD33: 109.6 | AE33: 115 | AG33: =AVERAGE(E33:Q33) -> 118.81538 | AH33: 114.1 | AI33: =AVERAGE(V33:X33) -> 107.1 | AJ33: =AVERAGE(S33:U33) -> 112.26667 | AK33: =AVERAGE(Y33:AD33) -> 109.23333
A34: 33 | B34: Rural+Urban | C34: 2013 | D34: November | E34: 118.1 | F34: 115.4 | G34: 118.7 | H34: 112.5 | I34: 106.8 | J34: 113.5 | K34: 183.1 | L34: 108.2 | M34: 102.2 | N34: 109.4 | O34: 111.8 | P34: 116.5 | Q34: 122.6 | R34: 113.1 | S34: 114.2 | T34: 111.9 | U34: 113.8 | V34: 100.4 | W34: 111.6 | X34: 111.1 | Y34: 109.3 | Z34: 109.5 | AA34: 108.6 | AB34: 111.2 | AC34: 108.1 | AD34: 109.7 | AE34: 116.3 | AG34: =AVERAGE(E34:Q34) -> 118.36923 | AH34: 113.1 | AI34: =AVERAGE(V34:X34) -> 107.7 | AJ34: =AVERAGE(S34:U34) -> 113.3 | AK34: =AVERAGE(Y34:AD34) -> 109.4
A35: 34 | B35: Rural | C35: 2013 | D35: December | E35: 118.4 | F35: 115.9 | G35: 120.4 | H35: 113.8 | I35: 109.5 | J35: 115.5 | K35: 145.7 | L35: 109.5 | M35: 102.9 | N35: 109.8 | O35: 112.1 | P35: 116.8 | Q35: 118.7 | R35: 113.6 | S35: 115.8 | T35: 114 | U35: 115.5 | V35: =VLOOKUP($A35,'Impute housing Missing Value'!$A$1:$C$125,3,0) -> 110.7 | W35: 112.8 | X35: 112.1 | Y35: 110.1 | Z35: 109.9 | AA35: 109.2 | AB35: 111.6 | AC35: 108.1 | AD35: 110.1 | AE35: 115.5 | AG35: =AVERAGE(E35:Q35) -> 116.07692 | AH35: 113.6 | AI35: =AVERAGE(V35:X35) -> 111.86667 | AJ35: =AVERAGE(S35:U35) -> 115.1 | AK35: =AVERAGE(Y35:AD35) -> 109.83333
A36: 35 | B36: Urban | C36: 2013 | D36: December | E36: 120.5 | F36: 118.1 | G36: 128.5 | H36: 112.8 | I36: 103.4 | J36: 110.7 | K36: 144.8 | L36: 107.1 | M36: 98.6 | N36: 111.9 | O36: 112.1 | P36: 118.1 | Q36: 117.8 | R36: 115 | S36: 114.2 | T36: 110.9 | U36: 113.7 | V36: 100.4 | W36: 110.4 | X36: 111.3 | Y36: 109 | Z36: 109.7 | AA36: 108.9 | AB36: 111.4 | AC36: 107.7 | AD36: 109.8 | AE36: 113.3 | AG36: =AVERAGE(E36:Q36) -> 115.72308 | AH36: 115 | AI36: =AVERAGE(V36:X36) -> 107.36667 | AJ36: =AVERAGE(S36:U36) -> 112.93333 | AK36: =AVERAGE(Y36:AD36) -> 109.41667
A37: 36 | B37: Rural+Urban | C37: 2013 | D37: December | E37: 119.1 | F37: 116.7 | G37: 123.5 | H37: 113.4 | I37: 107.3 | J37: 113.3 | K37: 145.4 | L37: 108.7 | M37: 101.5 | N37: 110.5 | O37: 112.1 | P37: 117.4 | Q37: 118.4 | R37: 114 | S37: 115.2 | T37: 112.7 | U37: 114.8 | V37: 100.4 | W37: 111.9 | X37: 111.7 | Y37: 109.7 | Z37: 109.8 | AA37: 109 | AB37: 111.5 | AC37: 107.9 | AD37: 110 | AE37: 114.5 | AG37: =AVERAGE(E37:Q37) -> 115.94615 | AH37: 114 | AI37: =AVERAGE(V37:X37) -> 108 | AJ37: =AVERAGE(S37:U37) -> 114.23333 | AK37: =AVERAGE(Y37:AD37) -> 109.65
A38: 37 | B38: Rural | C38: 2014 | D38: January | E38: 118.9 | F38: 117.1 | G38: 120.5 | H38: 114.4 | I38: 109 | J38: 115.5 | K38: 123.9 | L38: 109.6 | M38: 101.8 | N38: 110.2 | O38: 112.4 | P38: 117.3 | Q38: 116 | R38: 114 | S38: 116.5 | T38: 114.5 | U38: 116.2 | V38: =VLOOKUP($A38,'Impute housing Missing Value'!$A$1:$C$125,3,0) -> 111.6 | W38: 113 | X38: 112.6 | Y38: 110.6 | Z38: 110.5 | AA38: 109.6 | AB38: 111.8 | AC38: 108.3 | AD38: 110.6 | AE38: 114.2 | AG38: =AVERAGE(E38:Q38) -> 114.35385 | AH38: 114 | AI38: =AVERAGE(V38:X38) -> 112.4 | AJ38: =AVERAGE(S38:U38) -> 115.73333 | AK38: =AVERAGE(Y38:AD38) -> 110.23333
A39: 38 | B39: Urban | C39: 2014 | D39: January | E39: 121.2 | F39: 122 | G39: 129.9 | H39: 113.6 | I39: 102.9 | J39: 112.1 | K39: 118.9 | L39: 107.5 | M39: 96.9 | N39: 112.7 | O39: 112.1 | P39: 119 | Q39: 115.5 | R39: 115.7 | S39: 114.8 | T39: 111.3 | U39: 114.3 | V39: 100.4 | W39: 111 | X39: 111.9 | Y39: 109.7 | Z39: 110.8 | AA39: 109.8 | AB39: 111.5 | AC39: 108 | AD39: 110.5 | AE39: 112.9 | AG39: =AVERAGE(E39:Q39) -> 114.17692 | AH39: 115.7 | AI39: =AVERAGE(V39:X39) -> 107.76667 | AJ39: =AVERAGE(S39:U39) -> 113.46667 | AK39: =AVERAGE(Y39:AD39) -> 110.05
A40: 39 | B40: Rural+Urban | C40: 2014 | D40: January | E40: 119.6 | F40: 118.8 | G40: 124.1 | H40: 114.1 | I40: 106.8 | J40: 113.9 | K40: 122.2 | L40: 108.9 | M40: 100.2 | N40: 111 | O40: 112.3 | P40: 118.1 | Q40: 115.8 | R40: 114.5 | S40: 115.8 | T40: 113.2 | U40: 115.4 | V40: 100.4 | W40: 112.2 | X40: 112.3 | Y40: 110.3 | Z40: 110.7 | AA40: 109.7 | AB40: 111.6 | AC40: 108.2 | AD40: 110.6 | AE40: 113.6 | AG40: =AVERAGE(E40:Q40) -> 114.29231 | AH40: 114.5 | AI40: =AVERAGE(V40:X40) -> 108.3 | AJ40: =AVERAGE(S40:U40) -> 114.8 | AK40: =AVERAGE(Y40:AD40) -> 110.18333
...

Sheet Bucket
A1: Sector
A2: Year
A3: Month
A4: Cereals and products
A5: Meat and fish | E5: Food | G5: Pan, tobacco and intoxicants | I5: Clothing and footwear
A6: Egg | E6: Cereals and products | I6: Clothing
A7: Milk and products | E7: Meat and fish | I7: Footwear
A8: Oils and fats | E8: Egg | I8: Clothing and footwear
A9: Fruits | E9: Milk and products
A10: Vegetables | E10: Oils and fats | G10: House | I10: Others
A11: Pulses and products | E11: Fruits | G11: Housing | I11: Health
A12: Sugar and Confectionery | E12: Vegetables | G12: Fuel and light | I12: Transport and communication
A13: Spices | E13: Pulses and products | G13: Household goods and services | I13: Recreation and amusement
A14: Non-alcoholic beverages | E14: Sugar and Confectionery | I14: Education
A15: Prepared meals, snacks, sweets etc. | E15: Spices | I15: Personal care and effects
A16: Food and beverages | E16: Non-alcoholic beverages | I16: Miscellaneous
A17: Pan, tobacco and intoxicants | E17: Prepared meals, snacks, sweets etc.
A18: Clothing | E18: Food and beverages
A19: Footwear
A20: Clothing and footwear
A21: Housing
A22: Fuel and light
A23: Household goods and services
A24: Health
A25: Transport and communication
A26: Recreation and amusement
A27: Education
A28: Personal care and effects
A29: Miscellaneous
A30: General index

Sheet Impute housing Missing Value
B1: Sector | C1: Housing | F1: Sector | G1: Housing | J1: Sector | K1: Housing | M1: Year | N1: Month
A2: 1 | B2: Rural | C2: 100.3 | F2: Rural+Urban | G2: 100.3 | J2: Urban | K2: 100.3 | M2: 2013 | N2: January
A3: 4 | B3: Rural | C3: 100.4 | F3: Rural+Urban | G3: 100.4 | J3: Urban | K3: 100.4 | M3: 2013 | N3: February
A4: 7 | B4: Rural | C4: 100.4 | F4: Rural+Urban | G4: 100.4 | J4: Urban | K4: 100.4 | M4: 2013 | N4: March
A5: 10 | B5: Rural | C5: 100.5 | F5: Rural+Urban | G5: 100.5 | J5: Urban | K5: 100.5 | M5: 2013 | N5: April
A6: 13 | B6: Rural | C6: 100.5 | F6: Rural+Urban | G6: 100.5 | J6: Urban | K6: 100.5 | M6: 2013 | N6: May
A7: 16 | B7: Rural | C7: 106.6 | F7: Rural+Urban | G7: 106.6 | J7: Urban | K7: 106.6 | M7: 2013 | N7: June
A8: 19 | B8: Rural | C8: 107.7 | F8: Rural+Urban | G8: 107.7 | J8: Urban | K8: 107.7 | M8: 2013 | N8: July
A9: 22 | B9: Rural | C9: 108.9 | F9: Rural+Urban | G9: 108.9 | J9: Urban | K9: 108.9 | M9: 2013 | N9: August
A10: 25 | B10: Rural | C10: 109.7 | F10: Rural+Urban | G10: 109.7 | J10: Urban | K10: 109.7 | M10: 2013 | N10: September
A11: 28 | B11: Rural | C11: 110.5 | F11: Rural+Urban | G11: 110.5 | J11: Urban | K11: 110.5 | M11: 2013 | N11: October
A12: 31 | B12: Rural | C12: 111.1 | F12: Rural+Urban | G12: 111.1 | J12: Urban | K12: 111.1 | M12: 2013 | N12: November
A13: 34 | B13: Rural | C13: 110.7 | F13: Rural+Urban | G13: 110.7 | J13: Urban | K13: 110.7 | M13: 2013 | N13: December
... A88: 259 | B88: Rural | C88: 155.6 | F88: Rural+Urban | G88: 155.6 | J88: Urban | K88: 155.6 | M88: 2020 | N88: April
A89: 262 | B89: Rural | C89: 155.15 | F89: Rural+Urban | G89: 155.15 | J89: Urban | K89: =AVERAGE(K88,K90) -> 155.15 | M89: 2020 | N89: May
A90: 265 | B90: Rural | C90: 154.7 | F90: Rural+Urban | G90: 154.7 | J90: Urban | K90: 154.7 | M90: 2020 | N90: June
A91: 268 | B91: Rural | C91: 154.7 | F91: Rural+Urban | G91: 154.7 | J91: Urban | K91: 154.7 | M91: 2020 | N91: July
A92: 271 | B92: Rural | C92: 155.5 | F92: Rural+Urban | G92: 155.5 | J92: Urban | K92: 155.5 | M92: 2020 | N92: August
A93: 274 | B93: Rural | C93: 156.3 | F93: Rural+Urban | G93: 156.3 | J93: Urban | K93: 156.3 | M93: 2020 | N93: September
A94: 277 | B94: Rural | C94: 156.5 | F94: Rural+Urban | G94: 156.5 | J94: Urban | K94: 156.5 | M94: 2020 | N94: October
A95: 280 | B95: Rural | C95: 158 | F95: Rural+Urban | G95: 158 | J95: Urban | K95: 158 | M95: 2020 | N95: November
A96: 283 | B96: Rural | C96: 158.4 | F96: Rural+Urban | G96: 158.4 | J96: Urban | K96: 158.4 | M96: 2020 | N96: December
A97: 286 | B97: Rural | C97: 157.7 | F97: Rural+Urban | G97: 157.7 | J97: Urban | K97: 157.7 | M97: 2021 | N97: January
